Workbook

Sheet Co Packing Inputs
B2: Category | C2: Project Details | D2: Project Costs | E2: Overeage Req | G2: Customer Project Overview | H2: Inputs (landed) | J2: Raw Material | K2: Inputs (landed) | M2: =M26 -> 4oz Sachets - Packaging 1 | N2: Inputs (landed) | P2: =IF(H$4="","-",H$4 & " - Packaging 2") -> 4oz Tins - Packaging 2 | Q2: Inputs (landed) | S2: Packout 1 - Inners/ case | T2: Inputs | V2: Packout 2 - Shippers/ Outers | W2: Inputs | Y2: Packout 3 - Pallet | Z2: Inputs
B3: =J27 -> Materials - Req (g) | C3: =K27 -> 935550 | E3: =K3 -> 0.25 | G3: Packaging Type 1 - Individual Units | H3: 4oz Sachets | J3: Overrage Rate (%) | K3: 0.25 | M3: Overrage Rate (%) | N3: 0.15 | P3: Overrage Rate (%) | Q3: 0.03 | S3: Overrage Rate (%) | T3: 0.02 | V3: Overrage Rate (%) | W3: 0.01 | Y3: Outbound fee per/ pallet | Z3: 350
B4: =J28 -> Materials - Req (oz) | C4: =K28 -> 33000.555 | G4: Packaging Type 2 - Final Kit Units | H4: 4oz Tins | J4: Intake fee per/ pallet | K4: 195 | M4: Wage Rate | N4: 26 | P4: Wage Rate | Q4: 26 | S4: Wage Rate | T4: 26 | V4: Wage Rate | W4: 26 | Y4: Approx # of Pallets (if known)
B5: =J29 -> Materials - Req (lbs) | C5: =K29 -> 2062.5347 | D5: =K27*K9 -> 8632.6689 | G5: # of Units - Items per/ kit (packaging type 1) | H5: 6600 | J5: # of Pallets | K5: 1 | M5: Unit fill rate per/ min | N5: 12 | P5: Units per/ min | Q5: 15 | S5: Units per/ min | T5: 1 | V5: Units per/ min | W5: 1
B6: =J30 -> Materials - # of SKUs | C6: =K30 -> 1 | G6: # of Units - Final Kit (packaging type 2) | H6: 6600 | J6: # of Product SKUs | K6: 1 | M6: =IF(H$3="","",H$3 & " - Cost per/ unit") -> 4oz Sachets - Cost per/ unit | N6: 0.035 | P6: =IF(H$4="","-",H$4 & " - Cost per/ unit") -> 4oz Tins - Cost per/ unit | Q6: 0.55 | S6: Inners - Cost per/ inner | T6: 0.2 | V6: Shipper - Cost per/ shipper | W6: 0.2
B7: =J31 -> Materials - # of pallets | C7: =K31 -> 1 | G7: Unit size per/ ea (g) | H7: 113.4 | J7: Testing fee per/ sku | K7: 350 | M7: Label print - Cost per/ unit | N7: 0 | P7: Label Print Cost/ unit | Q7: 0.2 | S7: Carton Weight (g) | T7: 454 | V7: Carton Weight (g) | W7: 454
B8: =J32 -> Materials - Intake fee per/ pallet | C8: =K32 -> 243.75 | D8: =K4*K5 -> 195 | G8: Units per/ Inner (case pack) | H8: 24 | J8: Raw Material SKUs | K8: 1 | M8: Label apply rate per/ min | N8: 0 | P8: Tab Cost/ unit | Q8: 0 | S8: # of staff/ stations | T8: 1 | V8: # of staff/ stations | W8: 1
B9: =J33 -> Materials - Testing fee per/ sku | C9: =K33 -> 455 | D9: =K7*K8 -> 350 | G9: Inners per/ Master | H9: 0 | J9: Cost per/ gram | K9: 0.0092273731 | M9: Packagingt Weight (g) | N9: 1.6 | P9: Tab apply unit per/ min | Q9: 0 | S9: Hrs per/ shift | T9: 7.3 | V9: Hrs per/ shift | W9: 7.3
B10: =J34 -> Materials - Cost per/ gram | C10: =K34*K27 -> 34530.675 | D10: =K9*K27 -> 8632.6689 | G10: Project / Line Setup + QA Fee | H10: 1495 | J10: Left Over Inventory Cost | K10: 0 | M10: # of staff/ stations | N10: 5 | P10: Packaging Weight (g) | Q10: 71 | S10: Working Days (# of days) | T10: 5 | V10: Working Days (# of days) | W10: 5
B11: =M27 -> 4oz Sachets - Units Req | C11: =N27 -> 7590 | E11: =N3 -> 0.15 | G11: Unit of measurment | H11: g | J11: Left Over Inventory Absorb % | K11: 0 | M11: Hrs per/ shift | N11: 7.3 | P11: # of staff/ stations | Q11: 3
B12: =M28 -> 4oz Sachets - per/ min | C12: =N28 -> 9.6 | G12: PPU Denominator ** | H12: 6600 | M12: Working Days (# of days) | N12: 5.5 | P12: Hrs per/ shift | Q12: 7.3
B13: =M29 -> 4oz Sachets - per/ hr | C13: =N29 -> 576 | P13: Working Days (# of days) | Q13: 5
B14: =M30 -> 4oz Sachets - Total hrs req | C14: =N30 -> 13.177083
B15: =M31 -> 4oz Sachets - Total min req | C15: =N31 -> 790.625
B16: =M32 -> 4oz Sachets - cost/ per min | C16: =N32 -> 0.585 | G16: Customer Project Overview | H16: Outputs | J16: Mark Up - Raw | K16: Inputs | M16: Mark Up - Units | N16: Inputs | P16: Mark Up - Units | Q16: Inputs | S16: Mark Up % - Inners | T16: Inputs | V16: Mark Up % - Inners | W16: Inputs | Y16: Mark Up % - Inners | Z16: Inputs
B17: =M33 -> 4oz Sachets - Total labor | C17: =N33 -> 462.51562 | D17: =N30*N4 -> 342.60417 | G17: ="Total Kit Units - " & H3 -> Total Kit Units - 4oz Sachets | H17: =IF(H6>0, H5*H6/H6, H5) -> 6600 | J17: Intake fee per/ pallet | K17: 0.25 | M17: Efficiency buffer (%) | N17: 0.2 | P17: Efficiency buffer (%) | Q17: 0.2 | S17: Efficiency buffer (%) | T17: 0.2 | V17: Efficiency buffer (%) | W17: 0.25 | Y17: Outbound fee per/ pallet | Z17: 0.4
B18: =IF(H$3="","",H$3 & " - Total cost") -> 4oz Sachets - Total cost | C18: =N34*N27 -> 597.7125 | D18: =(N6*N27)+(N7*N27) -> 265.65 | G18: ="Total Kit Units - " & H4 -> Total Kit Units - 4oz Tins | H18: =MAX(H6, 0) -> 6600 | J18: Testing Fee | K18: 0.3 | M18: Labor cost | N18: 0.35 | P18: Labor cost | Q18: 0.35 | S18: Labor cost (%) | T18: 0.35 | V18: Labor cost (%) | W18: 0.35 | Y18: Added Pallets (Buffer) | Z18: 1
B19: =P27 -> 4oz Tins - Units Req | C19: =Q27 -> 6798 | E19: =Q3 -> 0.03 | G19: Total Grams Req (g) | H19: =IF(AND(H5>0, H6>0), H5, IF(H5>0, H5, H6)) * H7 -> 748440 | J19: Cost per/ gram | K19: 3 | M19: =IF(H$3="","",H$3 & " - Cost per/ unit") -> 4oz Sachets - Cost per/ unit | N19: 1.25 | P19: =IF(H$4="","",H$4 & " - Cost per/ unit") -> 4oz Tins - Cost per/ unit | Q19: 1.25 | S19: Inners - Cost per/ inner | T19: 1.25 | V19: Shipper - Cost per/ shipper | W19: 1.25
B20: =P28 -> 4oz Tins - per/ min | C20: =Q28 -> 12 | G20: Total Inners (Inners/ CDUs/ SRDs/ Cases) | H20: =IF(OR(H8=0, H8=""), 0, CEILING( IF(H6>0, H6, H5) / H8, 1) ) -> 275
B21: =P29 -> 4oz Tins - per/ hr | C21: =Q29 -> 720 | G21: Total Masters/ Shippers | H21: =IF(OR(H9<=0, H9=""), 0, CEILING( H20 / H9, 1) ) -> 0
B22: =P30 -> 4oz Tins - Total hrs req | C22: =Q30 -> 9.4416667 | G22: Project / Line Setup + QA - Our Cost | H22: =(H10-(H10*0.6))*K6 -> 598
B23: =P31 -> 4oz Tins - Total min req | C23: =Q31 -> 566.5 | G23: Lead Time - Days | H23: =SUM(K37,N37,Q37,T37,W37,Z37) -> 2.592656
B24: =P32 -> 4oz Tins - Labor cost/ per min | C24: =Q32 -> 0.585 | G24: Lead Time - Weeks | H24: =H23/5 -> 0.5185312
B25: =P33 -> 4oz Tins - Total labor | C25: =Q33 -> 331.4025 | D25: =Q4*Q30 -> 245.48333
B26: =IF(H$4="","-",H$4 & " - Total cost") -> 4oz Tins - Total cost | C26: =Q34*Q27 -> 11471.625 | D26: =SUM(Q6:Q8)*Q27 -> 5098.5 | G26: Added Lead Time (design/ materials) | H26: Inputs | J26: Raw Material | K26: Outputs | M26: =IF(H$3="","-",H$3 & " - Packaging 1") -> 4oz Sachets - Packaging 1 | N26: Outputs | P26: =IF(H$4="","-",H$4 & " - Packaging 2") -> 4oz Tins - Packaging 2 | Q26: Outputs | S26: =S2 -> Packout 1 - Inners/ case | T26: Outputs | V26: =V2 -> Packout 2 - Shippers/ Outers | W26: Outputs | Y26: =Y2 -> Packout 3 - Pallet | Z26: Outputs
B27: =S27 -> Inners - Packs Req | C27: =T27 -> 280.5 | E27: =T3 -> 0.02 | G27: Req Lead Time Buffer (added) | H27: 57 | J27: Materials - Req (g) | K27: =ROUNDUP(H19+(H19*K3),0) -> 935550 | M27: =IF(H$3="","-",H$3 & " - Units Req") -> 4oz Sachets - Units Req | N27: =ROUNDUP(H17+(N3*H17),0) -> 7590 | P27: =IF(H$4="","-",H$4 & " - Units Req") -> 4oz Tins - Units Req | Q27: =ROUNDUP(H18+(Q3*H18),0) -> 6798 | S27: Inners - Packs Req | T27: =H20+(T3*H20) -> 280.5 | V27: Shippers - Packs Req | W27: =H21+(W3*H21) -> 0 | Y27: Total Weight of Project (g) | Z27: =SUM(IFERROR(K35,0), IFERROR(N35,0), IFERROR(Q35,0), IFERROR(T35,0), IFERROR(W35,0)) -> 1539560
B28: =S28 -> Inners - per/ min | C28: =T28 -> 0.8 | J28: Materials - Req (oz) | K28: =K27/28.349523125 -> 33000.555 | M28: =IF(H$3="","-",H$3 & " - per/ min") -> 4oz Sachets - per/ min | N28: =IF(AND(N5>0,N8>0), (1/((1/N5)+(1/N8)))*(1-N17), IF(N5>0, N5*(1-N17), IF(N8>0, N8*(1-N17), 0 ) ) ) -> 9.6 | P28: =IF(H$4="","-",H$4 & " - per/ min") -> 4oz Tins - per/ min | Q28: =IF(AND(Q5>0,Q9>0), (1/((1/Q5)+(1/Q9)))*(1-Q17), IF(Q5>0, Q5*(1-Q17), IF(Q9>0, Q9*(1-Q17), 0 ) ) ) -> 12 | S28: Inners - per/ min | T28: =T5*(-T17)+T5 -> 0.8 | V28: Shippers - per/ min | W28: =W5*(-W17)+W5 -> 0.75 | Y28: Total Weight of Project (lbs) | Z28: =Z27 / 453.59237 -> 3394.1488
B29: =S29 -> Inners - per/ hr | C29: =T29 -> 48 | G29: Added Lead Time (design/ materials) | H29: Outputs | J29: Materials - Req (lbs) | K29: =K27/453.59237 -> 2062.5347 | M29: =IF(H$3="","-",H$3 & " - per/ hr") -> 4oz Sachets - per/ hr | N29: =N28*60 -> 576 | P29: =IF(H$4="","-",H$4 & " - per/ hr") -> 4oz Tins - per/ hr | Q29: =Q28*60 -> 720 | S29: Inners - per/ hr | T29: =T28*60 -> 48 | V29: Shippers - per/ hr | W29: =W28*60 -> 45 | Y29: Pallets - # of Pallets | Z29: =IF(OR(Z4="", Z4=0), IFERROR(CEILING(Z28/1200,1)+Z18, 0), Z4) -> 4
B30: =S30 -> Inners - Total hrs req | C30: =T30 -> 5.84375 | G30: Lead Time (days) | H30: =H23+H27 -> 59.592656 | J30: Materials - # of SKUs | K30: =K6 -> 1 | M30: =IF(H$3="","-",H$3 & " - Total hrs req") -> 4oz Sachets - Total hrs req | N30: =IFERROR(N31/60,0) -> 13.177083 | P30: =IF(H$4="","-",H$4 & " - Total hrs req") -> 4oz Tins - Total hrs req | Q30: =IFERROR(Q31/60,0) -> 9.4416667 | S30: Inners - Total hrs req | T30: =IFERROR(T31/60,0) -> 5.84375 | V30: Shippers - Total hrs req | W30: =IFERROR(W31/60,0) -> 0 | Y30: =IF(H$3="","",H$3 & " - Packaging 1") -> 4oz Sachets - Packaging 1 | Z30: =H17 -> 6600
B31: =S31 -> Inners - Total min req | C31: =T31 -> 350.625 | G31: Lead Time (weeks) | H31: =H30/5 -> 11.918531 | J31: Materials - # of pallets | K31: =K5 -> 1 | M31: =IF(H$3="","-",H$3 & " - Total min req") -> 4oz Sachets - Total min req | N31: =IFERROR(N27/N28,0) -> 790.625 | P31: =IF(H$4="","-",H$4 & " - Total min req") -> 4oz Tins - Total min req | Q31: =IFERROR(Q27/Q28,0) -> 566.5 | S31: Inners - Total min req | T31: =IFERROR(T27/T28,0) -> 350.625 | V31: Shippers - Total min req | W31: =IFERROR(W27/W28,0) -> 0 | Y31: =IF(H$4="","-",H$4 & " - Packaging 2") -> 4oz Tins - Packaging 2 | Z31: =H18 -> 6600
B32: =S32 -> Inners - cost/ per min | C32: =T32 -> 0.585 | J32: Materials - Intake fee per/ pallet | K32: =((K4*K17)+K4)*K5 -> 243.75 | M32: =IF(H$3="","-",H$3 & " - cost/ per min") -> 4oz Sachets - cost/ per min | N32: =IFERROR(N33/N31,0) -> 0.585 | P32: =IF(H$4="","-",H$4 & " - Labor cost/ per min") -> 4oz Tins - Labor cost/ per min | Q32: =IFERROR(Q33/Q31,0) -> 0.585 | S32: Inners - cost/ per min | T32: =IFERROR(T33/T31,0) -> 0.585 | V32: Shippers - cost/ per min | W32: =IFERROR(W33/W31,0) -> 0 | Y32: =G8 -> Units per/ Inner (case pack) | Z32: =T27 -> 280.5
B33: =S33 -> Inners - Labor Cost | C33: =T33 -> 205.11562 | D33: =T4*T30 -> 151.9375 | G33: Project Completion Dates | H33: Dates | J33: Materials - Testing fee per/ sku | K33: =(K7+(K7*K18))*K8 -> 455 | M33: =IF(H$3="","-",H$3 & " - Total labor") -> 4oz Sachets - Total labor | N33: =((N30*N4)*N18)+(N4*N30) -> 462.51562 | P33: =IF(H$4="","-",H$4 & " - Total labor") -> 4oz Tins - Total labor | Q33: =((Q30*Q4)*Q18)+(Q4*Q30) -> 331.4025 | S33: Inners - Labor Cost | T33: =((T30*T4)*T18)+(T4*T30) -> 205.11562 | V33: Shippers - Labor Cost | W33: =((W30*W4)*W18)+(W4*W30) -> 0 | Y33: Total Outers/ Master Shippers | Z33: =W27 -> 0
B34: =S34 -> Inners - Cost per/ inner | C34: =T34*T27 -> 126.225 | D34: =T6*T27 -> 56.1 | G34: Start Date | H34: 46090 | J34: Materials - Cost per/ gram | K34: =(K9 + ((1 - K11) * K10 / K27)) * (K19 + 1) -> 0.036909492 | M34: =IF(H$3="","-",H$3 & " - Cost per/ unit") -> 4oz Sachets - Cost per/ unit | N34: {=SUM((N6:N7)*N19)+SUM(N6:N7)} -> 0.07875 | P34: =IF(H$4="","-",H$4 & " - Mtrl cost per/ unit") -> 4oz Tins - Mtrl cost per/ unit | Q34: {=SUM((Q6:Q8)*Q19)+SUM(Q6:Q8)} -> 1.6875 | S34: Inners - Cost per/ inner | T34: =(T6*T19)+T6 -> 0.45 | V34: Shipper - Cost per/ shipper | W34: =(W6*W19)+W6 -> 0.45 | Y34: Pallets - Outbound fee/ pallet | Z34: =(Z3*Z17)+Z3 -> 490
B35: =V27 -> Shippers - Packs Req | C35: =W27 -> 0 | E35: =W3 -> 0.01 | G35: End Date | H35: =WORKDAY(H34,ROUNDUP(H30,0)) -> 46174 | J35: Materials - Total Weight | K35: =K27 -> 935550 | M35: =IF(H$3="","-",H$3 & " - Pkg 1 Total weight (g)") -> 4oz Sachets - Pkg 1 Total weight (g) | N35: =IFERROR(H17*N9,"") -> 10560 | P35: =IF(H$4="","-",H$4 & " - Pkg 2 Total weight (g)") -> 4oz Tins - Pkg 2 Total weight (g) | Q35: =IFERROR(H18*Q10,"") -> 468600 | S35: Inners - Total Inner weight (g) | T35: =IFERROR(T7*H20,"") -> 124850 | V35: Shipper - Total shipper weight (g) | W35: =IFERROR(W7*H21,"") -> 0 | Y35: Pallets - Total Fees | Z35: =Z29*Z34 -> 1960
B36: =V28 -> Shippers - per/ min | C36: =W28 -> 0.75
B37: =V29 -> Shippers - per/ hr | C37: =W29 -> 45 | J37: Pallets - Lead Time (days) | K37: =K5*0.2 -> 0.2 | M37: =IF(H$3="","-",H$3 & " - Lead Time (days)") -> 4oz Sachets - Lead Time (days) | N37: =N30 / (N10 * N11) -> 0.36101598 | P37: =IF(H$4="","-",H$4 & " - Lead Time (days)") -> 4oz Tins - Lead Time (days) | Q37: =Q30/(Q12*Q11) -> 0.43112633 | S37: Inners - Lead Time (days) | T37: =T30/(T9*T8) -> 0.8005137 | V37: Shippers - Lead Time (days) | W37: =W30/(W9*W8) -> 0 | Y37: Pallets - Lead Time (days) | Z37: =Z29*0.2 -> 0.8
B38: =V30 -> Shippers - Total hrs req | C38: =W30 -> 0 | G38: Conversion Calculator - $$ | H38: Input | J38: Pallets - Lead Time (weeks) | K38: =K37/5 -> 0.04 | M38: =IF(H$3="","-",H$3 & " - Lead Time (weeks)") -> 4oz Sachets - Lead Time (weeks) | N38: =N30/(N11*N10*N12) -> 0.065639269 | P38: =IF(H$4="","-",H$4 & " - Lead Time (weeks)") -> 4oz Tins - Lead Time (weeks) | Q38: =Q30/(Q12*Q11*Q13) -> 0.086225266 | S38: Inners - Lead Time (weeks) | T38: =T30/(T9*T8*T10) -> 0.16010274 | V38: Shippers - Lead Time (weeks) | W38: =W30/(W9*W8*W10) -> 0 | Y38: Pallets - Lead Time (weeks) | Z38: =Z37/5 -> 0.16
B39: =V31 -> Shippers - Total min req | C39: =W31 -> 0 | G39: Landed Price per/ lb (1 lb) | H39: 4.18
B40: =V32 -> Shippers - cost/ per min | C40: =W32 -> 0 | G40: Landed Price per/ oz | H40: =H39/16 -> 0.26125
B41: =V33 -> Shippers - Labor Cost | C41: =W33 -> 0 | D41: =W4*W30 -> 0 | G41: Landed Price per/ g | H41: =H39/453 -> 0.0092273731
...

Sheet Overview
B2: ='Co Packing Inputs'!B49 -> Total Project Costs | C2: Req'd Intake Qty | D2: To Be Delivered QTY | E2: Price | F2: PPU | H2: =B2 -> Total Project Costs | I2: ='Co Packing Inputs'!D49 -> Our Costs | J2: PPU Costs | K2: ='Co Packing Inputs'!H49 -> Margin %% | L2: Margin $$
B3: ='Co Packing Inputs'!B50 -> Project / Line Setup + QA | C3: ='Co Packing Inputs'!C6 -> 1 | D3: ='Co Packing Inputs'!C6 -> 1 | E3: ='Co Packing Inputs'!C50 -> 1495 | F3: =IFERROR(E3/D3, "$0.00") -> 1495 | H3: =B3 -> Project / Line Setup + QA | I3: ='Co Packing Inputs'!D50 -> 598 | J3: =IFERROR(I3/D3,0) -> 598 | K3: ='Co Packing Inputs'!H50 -> 0.6 | L3: =E3-I3 -> 897
B4: ='Co Packing Inputs'!B51 -> Material - Total | C4: ='Co Packing Inputs'!C3 -> 935550 | D4: ='Co Packing Inputs'!H19 -> 748440 | E4: ='Co Packing Inputs'!C51 -> 35229.425 | F4: =IFERROR(E4/D4, "$0.00") -> 0.047070474 | H4: =B4 -> Material - Total | I4: ='Co Packing Inputs'!D51 -> 9177.6689 | J4: =IFERROR(I4/D4,0) -> 0.012262398 | K4: ='Co Packing Inputs'!H51 -> 0.73948855 | L4: =E4-I4 -> 26051.757
B5: ='Co Packing Inputs'!B52 -> 4oz Sachets - Total | C5: ='Co Packing Inputs'!C11 -> 7590 | D5: ='Co Packing Inputs'!H17 -> 6600 | E5: ='Co Packing Inputs'!C52 -> 1060.2281 | F5: =IFERROR(E5/D5, "$0.00") -> 0.16064063 | H5: =B5 -> 4oz Sachets - Total | I5: ='Co Packing Inputs'!D52 -> 608.25417 | J5: =IFERROR(I5/D5,0) -> 0.092159722 | K5: ='Co Packing Inputs'!H52 -> 0.42629878 | L5: =E5-I5 -> 451.97396
B6: ='Co Packing Inputs'!B53 -> 4oz Tins - Total | C6: ='Co Packing Inputs'!Q27 -> 6798 | D6: ='Co Packing Inputs'!H18 -> 6600 | E6: ='Co Packing Inputs'!C53 -> 11803.028 | F6: =IFERROR(E6/D6, "$0.00") -> 1.7883375 | H6: =B6 -> 4oz Tins - Total | I6: ='Co Packing Inputs'!D53 -> 5343.9833 | J6: =IFERROR(I6/D6,0) -> 0.80969444 | K6: ='Co Packing Inputs'!H53 -> 0.54723622 | L6: =E6-I6 -> 6459.0442
B7: =IF('Co Packing Inputs'!H8="", 'Co Packing Inputs'!B54, "Inners (" & 'Co Packing Inputs'!H8 & " units per/ case) - Total") -> Inners (24 units per/ case) - Total | C7: ='Co Packing Inputs'!T27 -> 280.5 | D7: ='Co Packing Inputs'!H20 -> 275 | E7: ='Co Packing Inputs'!C54 -> 331.34062 | F7: =IFERROR(E7/D7, "$0.00") -> 1.204875 | H7: =B7 -> Inners (24 units per/ case) - Total | I7: ='Co Packing Inputs'!D54 -> 208.0375 | J7: =IFERROR(I7/D7,0) -> 0.7565 | K7: ='Co Packing Inputs'!H54 -> 0.37213404 | L7: =E7-I7 -> 123.30312
B8: =IF(OR('Co Packing Inputs'!H9="", 'Co Packing Inputs'!H9=0), 'Co Packing Inputs'!B55, "Master Shippers (" & 'Co Packing Inputs'!H9 & " inners/ per case) - Total") -> Master Shippers - Total | C8: ='Co Packing Inputs'!W27 -> 0 | D8: ='Co Packing Inputs'!H21 -> 0 | E8: ='Co Packing Inputs'!C55 -> 0 | F8: =IFERROR(E8/D8, "$0.00") -> $0.00 | H8: =B8 -> Master Shippers - Total | I8: ='Co Packing Inputs'!D55 -> 0 | J8: =IFERROR(I8/D8,0) -> 0 | K8: ='Co Packing Inputs'!H55 -> 0 | L8: =E8-I8 -> 0
B9: ='Co Packing Inputs'!B56 -> Pallet - Total | C9: ='Co Packing Inputs'!K5 -> 1 | D9: ='Co Packing Inputs'!Z29 -> 4 | E9: ='Co Packing Inputs'!C56 -> 1960 | F9: =IFERROR(E9/D9, "$0.00") -> 490 | H9: =B9 -> Pallet - Total | I9: ='Co Packing Inputs'!D56 -> 1400 | J9: =IFERROR(I9/D9,0) -> 350 | K9: ='Co Packing Inputs'!H56 -> 0.28571429 | L9: =E9-I9 -> 560
B10: ='Co Packing Inputs'!B57 -> TOTALS | E10: ='Co Packing Inputs'!C57 -> 51879.022 | F10: =E10/'Co Packing Inputs'!H12 -> 7.8604578 | H10: =B10 -> TOTALS | I10: ='Co Packing Inputs'!D57 -> 17335.944 | J10: =IFERROR(I10/'Co Packing Inputs'!H12,0) -> 2.6266582 | K10: ='Co Packing Inputs'!H57 -> 0.66583904 | L10: =E10-I10 -> 34543.078
B12: CUSTOMER FACING PRICE | E12: ='Co Packing Inputs'!C62 -> 34254 | F12: ='Co Packing Inputs'!C61 -> 5.19 | H12: ACTUAL TOTALS | I12: =I10 -> 17335.944 | J12: =J10 -> 2.6266582 | K12: ='Co Packing Inputs'!H61 -> 0.49390016 | L12: ='Co Packing Inputs'!G62 -> 16918.056
B14: Project Completion Dates | C14: Dates
B15: Lead Time (in weeks) | C15: ='Co Packing Inputs'!H31 -> 11.918531
B16: Start Date | C16: ='Co Packing Inputs'!H34 -> 46090
B17: End Date | C17: ='Co Packing Inputs'!H35 -> 46174
